Workbook

Sheet Backup Reservas
A1: Order# | B1: Account | C1: Name | D1: Branch | E1: SKU | F1: Quantity | G1: Type | H1: Conv PcxM3 | I1: M³ | J1: Specie | K1: Model | L1: Finish | M1: Size | N1: Lenght | O1: Subgroup | P1: Status
A2: 2509-720988 | B2: GF000041 | C2: OFF-QUALITY PRODUCTS | D2: 9007 | E2: TAYLNGVJ1614 | F2: 7 | G2: =_xlfn.XLOOKUP(E2,'Base SKUs'!E:E,'Base SKUs'!D:D) -> Thermowood | H2: =_xlfn.XLOOKUP(E2,'Base SKUs'!E:E,'Base SKUs'!S:S) -> 0.011172 | I2: =IF(OR(G2="Norx",K2="Tiles"),ROUND(F2,3),ROUND(F2*H2,3)) -> 0.078 | J2: =_xlfn.XLOOKUP(E2,'Base SKUs'!E:E,'Base SKUs'!G:G) -> Maximo Thermo Ayous | K2: =_xlfn.XLOOKUP(E2,'Base SKUs'!E:E,'Base SKUs'!H:H) -> VJoint - Nickel Gap | L2: =_xlfn.XLOOKUP(E2,'Base SKUs'!E:E,'Base SKUs'!I:I) -> - | M2: =_xlfn.XLOOKUP(E2,'Base SKUs'!E:E,'Base SKUs'!J:J) -> 1x6 | N2: =_xlfn.XLOOKUP(E2,'Base SKUs'!E:E,'Base SKUs'!K:K) -> 14 | O2: =_xlfn.XLOOKUP(E2,'Base SKUs'!E:E,'Base SKUs'!C:C) -> Long | P2: Damaged
A3: 2509-720988 | B3: GF000041 | C3: OFF-QUALITY PRODUCTS | D3: 9007 | E3: TAYLNGVJ1614 | F3: 31 | G3: =_xlfn.XLOOKUP(E3,'Base SKUs'!E:E,'Base SKUs'!D:D) -> Thermowood | H3: =_xlfn.XLOOKUP(E3,'Base SKUs'!E:E,'Base SKUs'!S:S) -> 0.011172 | I3: =IF(OR(G3="Norx",K3="Tiles"),ROUND(F3,3),ROUND(F3*H3,3)) -> 0.346 | J3: =_xlfn.XLOOKUP(E3,'Base SKUs'!E:E,'Base SKUs'!G:G) -> Maximo Thermo Ayous | K3: =_xlfn.XLOOKUP(E3,'Base SKUs'!E:E,'Base SKUs'!H:H) -> VJoint - Nickel Gap | L3: =_xlfn.XLOOKUP(E3,'Base SKUs'!E:E,'Base SKUs'!I:I) -> - | M3: =_xlfn.XLOOKUP(E3,'Base SKUs'!E:E,'Base SKUs'!J:J) -> 1x6 | N3: =_xlfn.XLOOKUP(E3,'Base SKUs'!E:E,'Base SKUs'!K:K) -> 14 | O3: =_xlfn.XLOOKUP(E3,'Base SKUs'!E:E,'Base SKUs'!C:C) -> Long | P3: Damaged
A4: 2509-724502 | B4: GF000041 | C4: OFF-QUALITY PRODUCTS | D4: 9008 | E4: IPEKD168S | F4: 56 | G4: =_xlfn.XLOOKUP(E4,'Base SKUs'!E:E,'Base SKUs'!D:D) -> Hardwoods | H4: =_xlfn.XLOOKUP(E4,'Base SKUs'!E:E,'Base SKUs'!S:S) -> 0.0064892773 | I4: =IF(OR(G4="Norx",K4="Tiles"),ROUND(F4,3),ROUND(F4*H4,3)) -> 0.363 | J4: =_xlfn.XLOOKUP(E4,'Base SKUs'!E:E,'Base SKUs'!G:G) -> Ipe | K4: =_xlfn.XLOOKUP(E4,'Base SKUs'!E:E,'Base SKUs'!H:H) -> S4S E4E | L4: =_xlfn.XLOOKUP(E4,'Base SKUs'!E:E,'Base SKUs'!I:I) -> - | M4: =_xlfn.XLOOKUP(E4,'Base SKUs'!E:E,'Base SKUs'!J:J) -> 1x6 | N4: =_xlfn.XLOOKUP(E4,'Base SKUs'!E:E,'Base SKUs'!K:K) -> 8 | O4: =_xlfn.XLOOKUP(E4,'Base SKUs'!E:E,'Base SKUs'!C:C) -> Long | P4: Damaged
A5: 2509-724589 | B5: GF000041 | C5: OFF-QUALITY PRODUCTS | D5: 9008 | E5: TAYLTG1610CL5 | F5: 18 | G5: =_xlfn.XLOOKUP(E5,'Base SKUs'!E:E,'Base SKUs'!D:D) -> Thermowood | H5: =_xlfn.XLOOKUP(E5,'Base SKUs'!E:E,'Base SKUs'!S:S) -> 0.00798 | I5: =IF(OR(G5="Norx",K5="Tiles"),ROUND(F5,3),ROUND(F5*H5,3)) -> 0.144 | J5: =_xlfn.XLOOKUP(E5,'Base SKUs'!E:E,'Base SKUs'!G:G) -> Maximo Thermo Ayous | K5: =_xlfn.XLOOKUP(E5,'Base SKUs'!E:E,'Base SKUs'!H:H) -> Fluted | L5: =_xlfn.XLOOKUP(E5,'Base SKUs'!E:E,'Base SKUs'!I:I) -> - | M5: =_xlfn.XLOOKUP(E5,'Base SKUs'!E:E,'Base SKUs'!J:J) -> 1x6 | N5: =_xlfn.XLOOKUP(E5,'Base SKUs'!E:E,'Base SKUs'!K:K) -> 10 | O5: =_xlfn.XLOOKUP(E5,'Base SKUs'!E:E,'Base SKUs'!C:C) -> Long | P5: Damaged
A6: 2509-724589 | B6: GF000041 | C6: OFF-QUALITY PRODUCTS | D6: 9008 | E6: TAYLTG1614CL5 | F6: 14 | G6: =_xlfn.XLOOKUP(E6,'Base SKUs'!E:E,'Base SKUs'!D:D) -> Thermowood | H6: =_xlfn.XLOOKUP(E6,'Base SKUs'!E:E,'Base SKUs'!S:S) -> 0.011172 | I6: =IF(OR(G6="Norx",K6="Tiles"),ROUND(F6,3),ROUND(F6*H6,3)) -> 0.156 | J6: =_xlfn.XLOOKUP(E6,'Base SKUs'!E:E,'Base SKUs'!G:G) -> Maximo Thermo Ayous | K6: =_xlfn.XLOOKUP(E6,'Base SKUs'!E:E,'Base SKUs'!H:H) -> Fluted | L6: =_xlfn.XLOOKUP(E6,'Base SKUs'!E:E,'Base SKUs'!I:I) -> - | M6: =_xlfn.XLOOKUP(E6,'Base SKUs'!E:E,'Base SKUs'!J:J) -> 1x6 | N6: =_xlfn.XLOOKUP(E6,'Base SKUs'!E:E,'Base SKUs'!K:K) -> 14 | O6: =_xlfn.XLOOKUP(E6,'Base SKUs'!E:E,'Base SKUs'!C:C) -> Long | P6: Damaged
A7: 2509-724589 | B7: GF000041 | C7: OFF-QUALITY PRODUCTS | D7: 9008 | E7: TAYLTG1615CL5 | F7: 5 | G7: =_xlfn.XLOOKUP(E7,'Base SKUs'!E:E,'Base SKUs'!D:D) -> Thermowood | H7: =_xlfn.XLOOKUP(E7,'Base SKUs'!E:E,'Base SKUs'!S:S) -> 0.01197 | I7: =IF(OR(G7="Norx",K7="Tiles"),ROUND(F7,3),ROUND(F7*H7,3)) -> 0.06 | J7: =_xlfn.XLOOKUP(E7,'Base SKUs'!E:E,'Base SKUs'!G:G) -> Maximo Thermo Ayous | K7: =_xlfn.XLOOKUP(E7,'Base SKUs'!E:E,'Base SKUs'!H:H) -> Fluted | L7: =_xlfn.XLOOKUP(E7,'Base SKUs'!E:E,'Base SKUs'!I:I) -> - | M7: =_xlfn.XLOOKUP(E7,'Base SKUs'!E:E,'Base SKUs'!J:J) -> 1x6 | N7: =_xlfn.XLOOKUP(E7,'Base SKUs'!E:E,'Base SKUs'!K:K) -> 15 | O7: =_xlfn.XLOOKUP(E7,'Base SKUs'!E:E,'Base SKUs'!C:C) -> Long | P7: Damaged
A8: 2509-724589 | B8: GF000041 | C8: OFF-QUALITY PRODUCTS | D8: 9008 | E8: TAYLTG168CL5 | F8: 245 | G8: =_xlfn.XLOOKUP(E8,'Base SKUs'!E:E,'Base SKUs'!D:D) -> Thermowood | H8: =_xlfn.XLOOKUP(E8,'Base SKUs'!E:E,'Base SKUs'!S:S) -> 0.006384 | I8: =IF(OR(G8="Norx",K8="Tiles"),ROUND(F8,3),ROUND(F8*H8,3)) -> 1.564 | J8: =_xlfn.XLOOKUP(E8,'Base SKUs'!E:E,'Base SKUs'!G:G) -> Maximo Thermo Ayous | K8: =_xlfn.XLOOKUP(E8,'Base SKUs'!E:E,'Base SKUs'!H:H) -> Fluted | L8: =_xlfn.XLOOKUP(E8,'Base SKUs'!E:E,'Base SKUs'!I:I) -> - | M8: =_xlfn.XLOOKUP(E8,'Base SKUs'!E:E,'Base SKUs'!J:J) -> 1x6 | N8: =_xlfn.XLOOKUP(E8,'Base SKUs'!E:E,'Base SKUs'!K:K) -> 8 | O8: =_xlfn.XLOOKUP(E8,'Base SKUs'!E:E,'Base SKUs'!C:C) -> Long | P8: Damaged
A9: 2509-724589 | B9: GF000041 | C9: OFF-QUALITY PRODUCTS | D9: 9008 | E9: TAYLTG169CL5 | F9: 28 | G9: =_xlfn.XLOOKUP(E9,'Base SKUs'!E:E,'Base SKUs'!D:D) -> Thermowood | H9: =_xlfn.XLOOKUP(E9,'Base SKUs'!E:E,'Base SKUs'!S:S) -> 0.007182 | I9: =IF(OR(G9="Norx",K9="Tiles"),ROUND(F9,3),ROUND(F9*H9,3)) -> 0.201 | J9: =_xlfn.XLOOKUP(E9,'Base SKUs'!E:E,'Base SKUs'!G:G) -> Maximo Thermo Ayous | K9: =_xlfn.XLOOKUP(E9,'Base SKUs'!E:E,'Base SKUs'!H:H) -> Fluted | L9: =_xlfn.XLOOKUP(E9,'Base SKUs'!E:E,'Base SKUs'!I:I) -> - | M9: =_xlfn.XLOOKUP(E9,'Base SKUs'!E:E,'Base SKUs'!J:J) -> 1x6 | N9: =_xlfn.XLOOKUP(E9,'Base SKUs'!E:E,'Base SKUs'!K:K) -> 9 | O9: =_xlfn.XLOOKUP(E9,'Base SKUs'!E:E,'Base SKUs'!C:C) -> Long | P9: Damaged
A10: 2509-726274 | B10: GF000014 | C10: GLOBAL FOREST LUMBER | D10: 9007 | E10: TAYVJ146 | F10: 11 | G10: =_xlfn.XLOOKUP(E10,'Base SKUs'!E:E,'Base SKUs'!D:D) -> Thermowood | H10: =_xlfn.XLOOKUP(E10,'Base SKUs'!E:E,'Base SKUs'!S:S) -> 0.0031464 | I10: =IF(OR(G10="Norx",K10="Tiles"),ROUND(F10,3),ROUND(F10*H10,3)) -> 0.035 | J10: =_xlfn.XLOOKUP(E10,'Base SKUs'!E:E,'Base SKUs'!G:G) -> Maximo Thermo Ayous | K10: =_xlfn.XLOOKUP(E10,'Base SKUs'!E:E,'Base SKUs'!H:H) -> VJoint - Square Back | L10: =_xlfn.XLOOKUP(E10,'Base SKUs'!E:E,'Base SKUs'!I:I) -> - | M10: =_xlfn.XLOOKUP(E10,'Base SKUs'!E:E,'Base SKUs'!J:J) -> 1x4 | N10: =_xlfn.XLOOKUP(E10,'Base SKUs'!E:E,'Base SKUs'!K:K) -> 6 | O10: =_xlfn.XLOOKUP(E10,'Base SKUs'!E:E,'Base SKUs'!C:C) -> Short | P10: Samples
A11: 2510-729499 | B11: GF000041 | C11: OFF-QUALITY PRODUCTS | D11: 9008 | E11: TAYLNGVJ168 | F11: 3 | G11: =_xlfn.XLOOKUP(E11,'Base SKUs'!E:E,'Base SKUs'!D:D) -> Thermowood | H11: =_xlfn.XLOOKUP(E11,'Base SKUs'!E:E,'Base SKUs'!S:S) -> 0.006384 | I11: =IF(OR(G11="Norx",K11="Tiles"),ROUND(F11,3),ROUND(F11*H11,3)) -> 0.019 | J11: =_xlfn.XLOOKUP(E11,'Base SKUs'!E:E,'Base SKUs'!G:G) -> Maximo Thermo Ayous | K11: =_xlfn.XLOOKUP(E11,'Base SKUs'!E:E,'Base SKUs'!H:H) -> VJoint - Nickel Gap | L11: =_xlfn.XLOOKUP(E11,'Base SKUs'!E:E,'Base SKUs'!I:I) -> - | M11: =_xlfn.XLOOKUP(E11,'Base SKUs'!E:E,'Base SKUs'!J:J) -> 1x6 | N11: =_xlfn.XLOOKUP(E11,'Base SKUs'!E:E,'Base SKUs'!K:K) -> 8 | O11: =_xlfn.XLOOKUP(E11,'Base SKUs'!E:E,'Base SKUs'!C:C) -> Long | P11: Damaged
A12: 2510-729499 | B12: GF000041 | C12: OFF-QUALITY PRODUCTS | D12: 9008 | E12: TAYLNGVJ1616 | F12: 9 | G12: =_xlfn.XLOOKUP(E12,'Base SKUs'!E:E,'Base SKUs'!D:D) -> Thermowood | H12: =_xlfn.XLOOKUP(E12,'Base SKUs'!E:E,'Base SKUs'!S:S) -> 0.012768 | I12: =IF(OR(G12="Norx",K12="Tiles"),ROUND(F12,3),ROUND(F12*H12,3)) -> 0.115 | J12: =_xlfn.XLOOKUP(E12,'Base SKUs'!E:E,'Base SKUs'!G:G) -> Maximo Thermo Ayous | K12: =_xlfn.XLOOKUP(E12,'Base SKUs'!E:E,'Base SKUs'!H:H) -> VJoint - Nickel Gap | L12: =_xlfn.XLOOKUP(E12,'Base SKUs'!E:E,'Base SKUs'!I:I) -> - | M12: =_xlfn.XLOOKUP(E12,'Base SKUs'!E:E,'Base SKUs'!J:J) -> 1x6 | N12: =_xlfn.XLOOKUP(E12,'Base SKUs'!E:E,'Base SKUs'!K:K) -> 16 | O12: =_xlfn.XLOOKUP(E12,'Base SKUs'!E:E,'Base SKUs'!C:C) -> Long | P12: Damaged
A13: 2510-729499 | B13: GF000041 | C13: OFF-QUALITY PRODUCTS | D13: 9008 | E13: TAYLNGVJ1614 | F13: 7 | G13: =_xlfn.XLOOKUP(E13,'Base SKUs'!E:E,'Base SKUs'!D:D) -> Thermowood | H13: =_xlfn.XLOOKUP(E13,'Base SKUs'!E:E,'Base SKUs'!S:S) -> 0.011172 | I13: =IF(OR(G13="Norx",K13="Tiles"),ROUND(F13,3),ROUND(F13*H13,3)) -> 0.078 | J13: =_xlfn.XLOOKUP(E13,'Base SKUs'!E:E,'Base SKUs'!G:G) -> Maximo Thermo Ayous | K13: =_xlfn.XLOOKUP(E13,'Base SKUs'!E:E,'Base SKUs'!H:H) -> VJoint - Nickel Gap | L13: =_xlfn.XLOOKUP(E13,'Base SKUs'!E:E,'Base SKUs'!I:I) -> - | M13: =_xlfn.XLOOKUP(E13,'Base SKUs'!E:E,'Base SKUs'!J:J) -> 1x6 | N13: =_xlfn.XLOOKUP(E13,'Base SKUs'!E:E,'Base SKUs'!K:K) -> 14 | O13: =_xlfn.XLOOKUP(E13,'Base SKUs'!E:E,'Base SKUs'!C:C) -> Long | P13: Damaged
... A453: 2609-818846 | B453: GF000029 | C453: RUSSIN LUMBER COMPANY | D453: 9007 | E453: IPE4128S | F453: 1 | G453: =_xlfn.XLOOKUP(E453,'Base SKUs'!E:E,'Base SKUs'!D:D) -> Hardwoods | H453: =_xlfn.XLOOKUP(E453,'Base SKUs'!E:E,'Base SKUs'!S:S) -> 0.061943102 | I453: =IF(OR(G453="Norx",K453="Tiles"),ROUND(F453,3),ROUND(F453*H453,3)) -> 0.062 | J453: =_xlfn.XLOOKUP(E453,'Base SKUs'!E:E,'Base SKUs'!G:G) -> Ipe | K453: =_xlfn.XLOOKUP(E453,'Base SKUs'!E:E,'Base SKUs'!H:H) -> S4S E4E | L453: =_xlfn.XLOOKUP(E453,'Base SKUs'!E:E,'Base SKUs'!I:I) -> - | M453: =_xlfn.XLOOKUP(E453,'Base SKUs'!E:E,'Base SKUs'!J:J) -> 4x12 | N453: =_xlfn.XLOOKUP(E453,'Base SKUs'!E:E,'Base SKUs'!K:K) -> 8 | O453: =_xlfn.XLOOKUP(E453,'Base SKUs'!E:E,'Base SKUs'!C:C) -> Long | P453: Sales

Sheet Base SKUs
A1: Family | B1: Group | C1: Subgroup | D1: Type | E1: SKU | F1: Description | G1: Specie | H1: Model | I1: Finish | J1: Size | K1: Length | L1: Lenght (m) | M1: Thick (mm) | N1: Width (mm) | O1: Conv L (pol) | P1: Conv T (pol) | Q1: Conv W (pol) | R1: Conv m3xLF | S1: Conv PcxM3 | T1: Description Code
A2: Accoya | B2: Accoya 4/4x6 | C2: Long | D2: Acetylated | E2: ARPRS44610 | F2: Maximo Accoya Rough Sawn 4/4x6 | G2: Maximo Accoya | H2: Rough Sawn | I2: - | J2: 4/4x6 | K2: 10 | L2: 3.048 | M2: 25.4 | N2: 146.05 | O2: =L2/0.0254 -> 120 | P2: =M2/25.4 -> 1 | Q2: =N2/25.4 -> 5.75 | R2: =ROUND(IFERROR(1/((M2*N2*0.3048)/1000000),0),3) -> 884.402 | S2: =L2*M2/1000*N2/1000 -> 0.011307074 | T2: =F2&" "&C2 -> Maximo Accoya Rough Sawn 4/4x6 Long
A3: Accoya | B3: Accoya 4/4x6 | C3: Long | D3: Acetylated | E3: ARPRS44611 | F3: Maximo Accoya Rough Sawn 4/4x6 | G3: Maximo Accoya | H3: Rough Sawn | I3: - | J3: 4/4x6 | K3: 11 | L3: 3.3528 | M3: 25.4 | N3: 146.05 | O3: =L3/0.0254 -> 132 | P3: =M3/25.4 -> 1 | Q3: =N3/25.4 -> 5.75 | R3: =ROUND(IFERROR(1/((M3*N3*0.3048)/1000000),0),3) -> 884.402 | S3: =L3*M3/1000*N3/1000 -> 0.012437782 | T3: =F3&" "&C3 -> Maximo Accoya Rough Sawn 4/4x6 Long
A4: Accoya | B4: Accoya 4/4x6 | C4: Long | D4: Acetylated | E4: ARPRS44612 | F4: Maximo Accoya Rough Sawn 4/4x6 | G4: Maximo Accoya | H4: Rough Sawn | I4: - | J4: 4/4x6 | K4: 12 | L4: 3.6576 | M4: 25.4 | N4: 146.05 | O4: =L4/0.0254 -> 144 | P4: =M4/25.4 -> 1 | Q4: =N4/25.4 -> 5.75 | R4: =ROUND(IFERROR(1/((M4*N4*0.3048)/1000000),0),3) -> 884.402 | S4: =L4*M4/1000*N4/1000 -> 0.013568489 | T4: =F4&" "&C4 -> Maximo Accoya Rough Sawn 4/4x6 Long
A5: Accoya | B5: Accoya 4/4x6 | C5: Long | D5: Acetylated | E5: ARPRS44613 | F5: Maximo Accoya Rough Sawn 4/4x6 | G5: Maximo Accoya | H5: Rough Sawn | I5: - | J5: 4/4x6 | K5: 13 | L5: 3.9624 | M5: 25.4 | N5: 146.05 | O5: =L5/0.0254 -> 156 | P5: =M5/25.4 -> 1 | Q5: =N5/25.4 -> 5.75 | R5: =ROUND(IFERROR(1/((M5*N5*0.3048)/1000000),0),3) -> 884.402 | S5: =L5*M5/1000*N5/1000 -> 0.014699196 | T5: =F5&" "&C5 -> Maximo Accoya Rough Sawn 4/4x6 Long
A6: Accoya | B6: Accoya 4/4x6 | C6: Long | D6: Acetylated | E6: ARPRS44614 | F6: Maximo Accoya Rough Sawn 4/4x6 | G6: Maximo Accoya | H6: Rough Sawn | I6: - | J6: 4/4x6 | K6: 14 | L6: 4.2672 | M6: 25.4 | N6: 146.05 | O6: =L6/0.0254 -> 168 | P6: =M6/25.4 -> 1 | Q6: =N6/25.4 -> 5.75 | R6: =ROUND(IFERROR(1/((M6*N6*0.3048)/1000000),0),3) -> 884.402 | S6: =L6*M6/1000*N6/1000 -> 0.015829904 | T6: =F6&" "&C6 -> Maximo Accoya Rough Sawn 4/4x6 Long
A7: Accoya | B7: Accoya 4/4x6 | C7: Long | D7: Acetylated | E7: ARPRS44615 | F7: Maximo Accoya Rough Sawn 4/4x6 | G7: Maximo Accoya | H7: Rough Sawn | I7: - | J7: 4/4x6 | K7: 15 | L7: 4.572 | M7: 25.4 | N7: 146.05 | O7: =L7/0.0254 -> 180 | P7: =M7/25.4 -> 1 | Q7: =N7/25.4 -> 5.75 | R7: =ROUND(IFERROR(1/((M7*N7*0.3048)/1000000),0),3) -> 884.402 | S7: =L7*M7/1000*N7/1000 -> 0.016960611 | T7: =F7&" "&C7 -> Maximo Accoya Rough Sawn 4/4x6 Long
A8: Accoya | B8: Accoya 4/4x6 | C8: Long | D8: Acetylated | E8: ARPRS44616 | F8: Maximo Accoya Rough Sawn 4/4x6 | G8: Maximo Accoya | H8: Rough Sawn | I8: - | J8: 4/4x6 | K8: 16 | L8: 4.8768 | M8: 25.4 | N8: 146.05 | O8: =L8/0.0254 -> 192 | P8: =M8/25.4 -> 1 | Q8: =N8/25.4 -> 5.75 | R8: =ROUND(IFERROR(1/((M8*N8*0.3048)/1000000),0),3) -> 884.402 | S8: =L8*M8/1000*N8/1000 -> 0.018091319 | T8: =F8&" "&C8 -> Maximo Accoya Rough Sawn 4/4x6 Long
A9: Accoya | B9: Accoya 4/4x6 | C9: Long | D9: Acetylated | E9: ARPRS4468 | F9: Maximo Accoya Rough Sawn 4/4x6 | G9: Maximo Accoya | H9: Rough Sawn | I9: - | J9: 4/4x6 | K9: 8 | L9: 2.4384 | M9: 25.4 | N9: 146.05 | O9: =L9/0.0254 -> 96 | P9: =M9/25.4 -> 1 | Q9: =N9/25.4 -> 5.75 | R9: =ROUND(IFERROR(1/((M9*N9*0.3048)/1000000),0),3) -> 884.402 | S9: =L9*M9/1000*N9/1000 -> 0.0090456593 | T9: =F9&" "&C9 -> Maximo Accoya Rough Sawn 4/4x6 Long
A10: Accoya | B10: Accoya 4/4x6 | C10: Long | D10: Acetylated | E10: ARPRS4469 | F10: Maximo Accoya Rough Sawn 4/4x6 | G10: Maximo Accoya | H10: Rough Sawn | I10: - | J10: 4/4x6 | K10: 9 | L10: 2.7432 | M10: 25.4 | N10: 146.05 | O10: =L10/0.0254 -> 108 | P10: =M10/25.4 -> 1 | Q10: =N10/25.4 -> 5.75 | R10: =ROUND(IFERROR(1/((M10*N10*0.3048)/1000000),0),3) -> 884.402 | S10: =L10*M10/1000*N10/1000 -> 0.010176367 | T10: =F10&" "&C10 -> Maximo Accoya Rough Sawn 4/4x6 Long
A11: Accoya | B11: Accoya 4/4x6 | C11: Long | D11: Acetylated | E11: ARPRS54610 | F11: Maximo Accoya Rough Sawn 5/4x6 | G11: Maximo Accoya | H11: Rough Sawn | I11: - | J11: 5/4x6 | K11: 10 | L11: 3.048 | M11: 25.4 | N11: 146.05 | O11: =L11/0.0254 -> 120 | P11: =M11/25.4 -> 1 | Q11: =N11/25.4 -> 5.75 | R11: =ROUND(IFERROR(1/((M11*N11*0.3048)/1000000),0),3) -> 884.402 | S11: =L11*M11/1000*N11/1000 -> 0.011307074 | T11: =F11&" "&C11 -> Maximo Accoya Rough Sawn 5/4x6 Long
A12: Accoya | B12: Accoya 4/4x6 | C12: Long | D12: Acetylated | E12: ARPRS54611 | F12: Maximo Accoya Rough Sawn 5/4x6 | G12: Maximo Accoya | H12: Rough Sawn | I12: - | J12: 5/4x6 | K12: 11 | L12: 3.3528 | M12: 25.4 | N12: 146.05 | O12: =L12/0.0254 -> 132 | P12: =M12/25.4 -> 1 | Q12: =N12/25.4 -> 5.75 | R12: =ROUND(IFERROR(1/((M12*N12*0.3048)/1000000),0),3) -> 884.402 | S12: =L12*M12/1000*N12/1000 -> 0.012437782 | T12: =F12&" "&C12 -> Maximo Accoya Rough Sawn 5/4x6 Long
A13: Accoya | B13: Accoya 4/4x6 | C13: Long | D13: Acetylated | E13: ARPRS54612 | F13: Maximo Accoya Rough Sawn 5/4x6 | G13: Maximo Accoya | H13: Rough Sawn | I13: - | J13: 5/4x6 | K13: 12 | L13: 3.6576 | M13: 25.4 | N13: 146.05 | O13: =L13/0.0254 -> 144 | P13: =M13/25.4 -> 1 | Q13: =N13/25.4 -> 5.75 | R13: =ROUND(IFERROR(1/((M13*N13*0.3048)/1000000),0),3) -> 884.402 | S13: =L13*M13/1000*N13/1000 -> 0.013568489 | T13: =F13&" "&C13 -> Maximo Accoya Rough Sawn 5/4x6 Long
... A183: Angelim | B183: Angelim 2x8 A | C183: Long | D183: Hardwoods | E183: AGKD84823RS | F183: Angelim Pedra Rough Sawn 2x8 A | G183: Angelim Pedra | H183: Rough Sawn | I183: - | J183: 2x8 A | K183: 23 | L183: 7.0104 | M183: 50.8 | N183: 203.2 | O183: =L183/0.0254 -> 276 | P183: =M183/25.4 -> 2 | Q183: =N183/25.4 -> 8 | R183: =ROUND(IFERROR(1/((M183*N183*0.3048)/1000000),0),3) -> 317.832 | S183: =L183*M183/1000*N183/1000 -> 0.072365275 | T183: =F183&" "&C183 -> Angelim Pedra Rough Sawn 2x8 A Long
A184: Angelim | B184: Angelim 43x68 | C184: Long | D184: Hardwoods | E184: AGKD436810S | F184: Angelim Pedra S4S E4E 43x68 | G184: Angelim Pedra | H184: S4S E4E | I184: - | J184: 43x68 | K184: 10 | L184: =K184*0.3048 -> 3.048 | M184: 43 | N184: 68 | O184: =L184/0.0254 -> 120 | P184: =M184/25.4 -> 1.6929134 | Q184: =N184/25.4 -> 2.6771654 | R184: =ROUND(IFERROR(1/((M184*N184*0.3048)/1000000),0),3) -> 1122.038 | S184: =L184*M184/1000*N184/1000 -> 0.008912352 | T184: =F184&" "&C184 -> Angelim Pedra S4S E4E 43x68 Long
A185: Angelim | B185: Angelim 43x68 | C185: Long | D185: Hardwoods | E185: AGKD436811S | F185: Angelim Pedra S4S E4E 43x68 | G185: Angelim Pedra | H185: S4S E4E | I185: - | J185: 43x68 | K185: 11 | L185: =K185*0.3048 -> 3.3528 | M185: 43 | N185: 68 | O185: =L185/0.0254 -> 132 | P185: =M185/25.4 -> 1.6929134 | Q185: =N185/25.4 -> 2.6771654 | R185: =ROUND(IFERROR(1/((M185*N185*0.3048)/1000000),0),3) -> 1122.038 | S185: =L185*M185/1000*N185/1000 -> 0.0098035872 | T185: =F185&" "&C185 -> Angelim Pedra S4S E4E 43x68 Long
A186: Angelim | B186: Angelim 43x68 | C186: Long | D186: Hardwoods | E186: AGKD436812S | F186: Angelim Pedra S4S E4E 43x68 | G186: Angelim Pedra | H186: S4S E4E | I186: - | J186: 43x68 | K186: 12 | L186: =K186*0.3048 -> 3.6576 | M186: 43 | N186: 68 | O186: =L186/0.0254 -> 144 | P186: =M186/25.4 -> 1.6929134 | Q186: =N186/25.4 -> 2.6771654 | R186: =ROUND(IFERROR(1/((M186*N186*0.3048)/1000000),0),3) -> 1122.038 | S186: =L186*M186/1000*N186/1000 -> 0.010694822 | T186: =F186&" "&C186 -> Angelim Pedra S4S E4E 43x68 Long
A187: Angelim | B187: Angelim 43x68 | C187: Long | D187: Hardwoods | E187: AGKD436813S | F187: Angelim Pedra S4S E4E 43x68 | G187: Angelim Pedra | H187: S4S E4E | I187: - | J187: 43x68 | K187: 13 | L187: =K187*0.3048 -> 3.9624 | M187: 43 | N187: 68 | O187: =L187/0.0254 -> 156 | P187: =M187/25.4 -> 1.6929134 | Q187: =N187/25.4 -> 2.6771654 | R187: =ROUND(IFERROR(1/((M187*N187*0.3048)/1000000),0),3) -> 1122.038 | S187: =L187*M187/1000*N187/1000 -> 0.011586058 | T187: =F187&" "&C187 -> Angelim Pedra S4S E4E 43x68 Long
A188: Angelim | B188: Angelim 43x68 | C188: Long | D188: Hardwoods | E188: AGKD436814S | F188: Angelim Pedra S4S E4E 43x68 | G188: Angelim Pedra | H188: S4S E4E | I188: - | J188: 43x68 | K188: 14 | L188: =K188*0.3048 -> 4.2672 | M188: 43 | N188: 68 | O188: =L188/0.0254 -> 168 | P188: =M188/25.4 -> 1.6929134 | Q188: =N188/25.4 -> 2.6771654 | R188: =ROUND(IFERROR(1/((M188*N188*0.3048)/1000000),0),3) -> 1122.038 | S188: =L188*M188/1000*N188/1000 -> 0.012477293 | T188: =F188&" "&C188 -> Angelim Pedra S4S E4E 43x68 Long
A189: Angelim | B189: Angelim 43x68 | C189: Long | D189: Hardwoods | E189: AGKD436815S | F189: Angelim Pedra S4S E4E 43x68 | G189: Angelim Pedra | H189: S4S E4E | I189: - | J189: 43x68 | K189: 15 | L189: =K189*0.3048 -> 4.572 | M189: 43 | N189: 68 | O189: =L189/0.0254 -> 180 | P189: =M189/25.4 -> 1.6929134 | Q189: =N189/25.4 -> 2.6771654 | R189: =ROUND(IFERROR(1/((M189*N189*0.3048)/1000000),0),3) -> 1122.038 | S189: =L189*M189/1000*N189/1000 -> 0.013368528 | T189: =F189&" "&C189 -> Angelim Pedra S4S E4E 43x68 Long
A190: Angelim | B190: Angelim 43x68 | C190: Long | D190: Hardwoods | E190: AGKD436816S | F190: Angelim Pedra S4S E4E 43x68 | G190: Angelim Pedra | H190: S4S E4E | I190: - | J190: 43x68 | K190: 16 | L190: =K190*0.3048 -> 4.8768 | M190: 43 | N190: 68 | O190: =L190/0.0254 -> 192 | P190: =M190/25.4 -> 1.6929134 | Q190: =N190/25.4 -> 2.6771654 | R190: =ROUND(IFERROR(1/((M190*N190*0.3048)/1000000),0),3) -> 1122.038 | S190: =L190*M190/1000*N190/1000 -> 0.014259763 | T190: =F190&" "&C190 -> Angelim Pedra S4S E4E 43x68 Long
A191: Angelim | B191: Angelim 43x68 | C191: Long | D191: Hardwoods | E191: AGKD436817S | F191: Angelim Pedra S4S E4E 43x68 | G191: Angelim Pedra | H191: S4S E4E | I191: - | J191: 43x68 | K191: 17 | L191: =K191*0.3048 -> 5.1816 | M191: 43 | N191: 68 | O191: =L191/0.0254 -> 204 | P191: =M191/25.4 -> 1.6929134 | Q191: =N191/25.4 -> 2.6771654 | R191: =ROUND(IFERROR(1/((M191*N191*0.3048)/1000000),0),3) -> 1122.038 | S191: =L191*M191/1000*N191/1000 -> 0.015150998 | T191: =F191&" "&C191 -> Angelim Pedra S4S E4E 43x68 Long
A192: Angelim | B192: Angelim 43x68 | C192: Long | D192: Hardwoods | E192: AGKD436818S | F192: Angelim Pedra S4S E4E 43x68 | G192: Angelim Pedra | H192: S4S E4E | I192: - | J192: 43x68 | K192: 18 | L192: =K192*0.3048 -> 5.4864 | M192: 43 | N192: 68 | O192: =L192/0.0254 -> 216 | P192: =M192/25.4 -> 1.6929134 | Q192: =N192/25.4 -> 2.6771654 | R192: =ROUND(IFERROR(1/((M192*N192*0.3048)/1000000),0),3) -> 1122.038 | S192: =L192*M192/1000*N192/1000 -> 0.016042234 | T192: =F192&" "&C192 -> Angelim Pedra S4S E4E 43x68 Long
A193: Angelim | B193: Angelim 43x68 | C193: Long | D193: Hardwoods | E193: AGKD436819S | F193: Angelim Pedra S4S E4E 43x68 | G193: Angelim Pedra | H193: S4S E4E | I193: - | J193: 43x68 | K193: 19 | L193: =K193*0.3048 -> 5.7912 | M193: 43 | N193: 68 | O193: =L193/0.0254 -> 228 | P193: =M193/25.4 -> 1.6929134 | Q193: =N193/25.4 -> 2.6771654 | R193: =ROUND(IFERROR(1/((M193*N193*0.3048)/1000000),0),3) -> 1122.038 | S193: =L193*M193/1000*N193/1000 -> 0.016933469 | T193: =F193&" "&C193 -> Angelim Pedra S4S E4E 43x68 Long
A194: Angelim | B194: Angelim 43x68 | C194: Long | D194: Hardwoods | E194: AGKD436820S | F194: Angelim Pedra S4S E4E 43x68 | G194: Angelim Pedra | H194: S4S E4E | I194: - | J194: 43x68 | K194: 20 | L194: =K194*0.3048 -> 6.096 | M194: 43 | N194: 68 | O194: =L194/0.0254 -> 240 | P194: =M194/25.4 -> 1.6929134 | Q194: =N194/25.4 -> 2.6771654 | R194: =ROUND(IFERROR(1/((M194*N194*0.3048)/1000000),0),3) -> 1122.038 | S194: =L194*M194/1000*N194/1000 -> 0.017824704 | T194: =F194&" "&C194 -> Angelim Pedra S4S E4E 43x68 Long
A195: Angelim | B195: Angelim 43x68 | C195: Long | D195: Hardwoods | E195: AGKD436821S | F195: Angelim Pedra S4S E4E 43x68 | G195: Angelim Pedra | H195: S4S E4E | I195: - | J195: 43x68 | K195: 21 | L195: =K195*0.3048 -> 6.4008 | M195: 43 | N195: 68 | O195: =L195/0.0254 -> 252 | P195: =M195/25.4 -> 1.6929134 | Q195: =N195/25.4 -> 2.6771654 | R195: =ROUND(IFERROR(1/((M195*N195*0.3048)/1000000),0),3) -> 1122.038 | S195: =L195*M195/1000*N195/1000 -> 0.018715939 | T195: =F195&" "&C195 -> Angelim Pedra S4S E4E 43x68 Long
... A204: Angelim | B204: Angelim 43x68 | C204: Long | D204: Hardwoods | E204: AGKD43689S | F204: Angelim Pedra S4S E4E 43x68 | G204: Angelim Pedra | H204: S4S E4E | I204: - | J204: 43x68 | K204: 9 | L204: =K204*0.3048 -> 2.7432 | M204: 43 | N204: 68 | O204: =L204/0.0254 -> 108 | P204: =M204/25.4 -> 1.6929134 | Q204: =N204/25.4 -> 2.6771654 | R204: =ROUND(IFERROR(1/((M204*N204*0.3048)/1000000),0),3) -> 1122.038 | S204: =L204*M204/1000*N204/1000 -> 0.0080211168 | T204: =F204&" "&C204 -> Angelim Pedra S4S E4E 43x68 Long
A205: Cumaru | B205: Cumaru 5/4x6 | C205: Long | D205: Hardwoods | E205: CMKD54610G | F205: Cumaru Grooved 5/4x6 | G205: Cumaru | H205: Grooved | I205: - | J205: 5/4x6 | K205: 10 | L205: 3.048 | M205: 25.4 | N205: 139.7 | O205: =L205/0.0254 -> 120 | P205: =M205/25.4 -> 1 | Q205: =N205/25.4 -> 5.5 | R205: =ROUND(IFERROR(1/((M205*N205*0.3048)/1000000),0),3) -> 924.602 | S205: =L205*M205/1000*N205/1000 -> 0.010815462 | T205: =F205&" "&C205 -> Cumaru Grooved 5/4x6 Long
A206: Cumaru | B206: Cumaru 5/4x6 | C206: Long | D206: Hardwoods | E206: CMKD54611G | F206: Cumaru Grooved 5/4x6 | G206: Cumaru | H206: Grooved | I206: - | J206: 5/4x6 | K206: 11 | L206: 3.3528 | M206: 25.4 | N206: 139.7 | O206: =L206/0.0254 -> 132 | P206: =M206/25.4 -> 1 | Q206: =N206/25.4 -> 5.5 | R206: =ROUND(IFERROR(1/((M206*N206*0.3048)/1000000),0),3) -> 924.602 | S206: =L206*M206/1000*N206/1000 -> 0.011897008 | T206: =F206&" "&C206 -> Cumaru Grooved 5/4x6 Long
A207: Cumaru | B207: Cumaru 5/4x6 | C207: Long | D207: Hardwoods | E207: CMKD54612G | F207: Cumaru Grooved 5/4x6 | G207: Cumaru | H207: Grooved | I207: - | J207: 5/4x6 | K207: 12 | L207: 3.6576 | M207: 25.4 | N207: 139.7 | O207: =L207/0.0254 -> 144 | P207: =M207/25.4 -> 1 | Q207: =N207/25.4 -> 5.5 | R207: =ROUND(IFERROR(1/((M207*N207*0.3048)/1000000),0),3) -> 924.602 | S207: =L207*M207/1000*N207/1000 -> 0.012978555 | T207: =F207&" "&C207 -> Cumaru Grooved 5/4x6 Long
A208: Cumaru | B208: Cumaru 5/4x6 | C208: Long | D208: Hardwoods | E208: CMKD54613G | F208: Cumaru Grooved 5/4x6 | G208: Cumaru | H208: Grooved | I208: - | J208: 5/4x6 | K208: 13 | L208: 3.9624 | M208: 25.4 | N208: 139.7 | O208: =L208/0.0254 -> 156 | P208: =M208/25.4 -> 1 | Q208: =N208/25.4 -> 5.5 | R208: =ROUND(IFERROR(1/((M208*N208*0.3048)/1000000),0),3) -> 924.602 | S208: =L208*M208/1000*N208/1000 -> 0.014060101 | T208: =F208&" "&C208 -> Cumaru Grooved 5/4x6 Long
A209: Cumaru | B209: Cumaru 5/4x6 | C209: Long | D209: Hardwoods | E209: CMKD54614G | F209: Cumaru Grooved 5/4x6 | G209: Cumaru | H209: Grooved | I209: - | J209: 5/4x6 | K209: 14 | L209: 4.2672 | M209: 25.4 | N209: 139.7 | O209: =L209/0.0254 -> 168 | P209: =M209/25.4 -> 1 | Q209: =N209/25.4 -> 5.5 | R209: =ROUND(IFERROR(1/((M209*N209*0.3048)/1000000),0),3) -> 924.602 | S209: =L209*M209/1000*N209/1000 -> 0.015141647 | T209: =F209&" "&C209 -> Cumaru Grooved 5/4x6 Long
A210: Cumaru | B210: Cumaru 5/4x6 | C210: Long | D210: Hardwoods | E210: CMKD54615G | F210: Cumaru Grooved 5/4x6 | G210: Cumaru | H210: Grooved | I210: - | J210: 5/4x6 | K210: 15 | L210: 4.572 | M210: 25.4 | N210: 139.7 | O210: =L210/0.0254 -> 180 | P210: =M210/25.4 -> 1 | Q210: =N210/25.4 -> 5.5 | R210: =ROUND(IFERROR(1/((M210*N210*0.3048)/1000000),0),3) -> 924.602 | S210: =L210*M210/1000*N210/1000 -> 0.016223193 | T210: =F210&" "&C210 -> Cumaru Grooved 5/4x6 Long
A211: Cumaru | B211: Cumaru 5/4x6 | C211: Long | D211: Hardwoods | E211: CMKD54616G | F211: Cumaru Grooved 5/4x6 | G211: Cumaru | H211: Grooved | I211: - | J211: 5/4x6 | K211: 16 | L211: 4.8768 | M211: 25.4 | N211: 139.7 | O211: =L211/0.0254 -> 192 | P211: =M211/25.4 -> 1 | Q211: =N211/25.4 -> 5.5 | R211: =ROUND(IFERROR(1/((M211*N211*0.3048)/1000000),0),3) -> 924.602 | S211: =L211*M211/1000*N211/1000 -> 0.01730474 | T211: =F211&" "&C211 -> Cumaru Grooved 5/4x6 Long
A212: Cumaru | B212: Cumaru 5/4x6 | C212: Long | D212: Hardwoods | E212: CMKD54617G | F212: Cumaru Grooved 5/4x6 | G212: Cumaru | H212: Grooved | I212: - | J212: 5/4x6 | K212: 17 | L212: 5.1816 | M212: 25.4 | N212: 139.7 | O212: =L212/0.0254 -> 204 | P212: =M212/25.4 -> 1 | Q212: =N212/25.4 -> 5.5 | R212: =ROUND(IFERROR(1/((M212*N212*0.3048)/1000000),0),3) -> 924.602 | S212: =L212*M212/1000*N212/1000 -> 0.018386286 | T212: =F212&" "&C212 -> Cumaru Grooved 5/4x6 Long
A213: Cumaru | B213: Cumaru 5/4x6 | C213: Long | D213: Hardwoods | E213: CMKD54618G | F213: Cumaru Grooved 5/4x6 | G213: Cumaru | H213: Grooved | I213: - | J213: 5/4x6 | K213: 18 | L213: 5.4864 | M213: 25.4 | N213: 139.7 | O213: =L213/0.0254 -> 216 | P213: =M213/25.4 -> 1 | Q213: =N213/25.4 -> 5.5 | R213: =ROUND(IFERROR(1/((M213*N213*0.3048)/1000000),0),3) -> 924.602 | S213: =L213*M213/1000*N213/1000 -> 0.019467832 | T213: =F213&" "&C213 -> Cumaru Grooved 5/4x6 Long
A214: Cumaru | B214: Cumaru 5/4x6 | C214: Long | D214: Hardwoods | E214: CMKD54619G | F214: Cumaru Grooved 5/4x6 | G214: Cumaru | H214: Grooved | I214: - | J214: 5/4x6 | K214: 19 | L214: 5.7912 | M214: 25.4 | N214: 139.7 | O214: =L214/0.0254 -> 228 | P214: =M214/25.4 -> 1 | Q214: =N214/25.4 -> 5.5 | R214: =ROUND(IFERROR(1/((M214*N214*0.3048)/1000000),0),3) -> 924.602 | S214: =L214*M214/1000*N214/1000 -> 0.020549378 | T214: =F214&" "&C214 -> Cumaru Grooved 5/4x6 Long
A215: Cumaru | B215: Cumaru 5/4x6 | C215: Long | D215: Hardwoods | E215: CMKD54620G | F215: Cumaru Grooved 5/4x6 | G215: Cumaru | H215: Grooved | I215: - | J215: 5/4x6 | K215: 20 | L215: 6.096 | M215: 25.4 | N215: 139.7 | O215: =L215/0.0254 -> 240 | P215: =M215/25.4 -> 1 | Q215: =N215/25.4 -> 5.5 | R215: =ROUND(IFERROR(1/((M215*N215*0.3048)/1000000),0),3) -> 924.602 | S215: =L215*M215/1000*N215/1000 -> 0.021630924 | T215: =F215&" "&C215 -> Cumaru Grooved 5/4x6 Long
A216: Cumaru | B216: Cumaru 5/4x6 | C216: Long | D216: Hardwoods | E216: CMKD54621G | F216: Cumaru Grooved 5/4x6 | G216: Cumaru | H216: Grooved | I216: - | J216: 5/4x6 | K216: 21 | L216: 6.4008 | M216: 25.4 | N216: 139.7 | O216: =L216/0.0254 -> 252 | P216: =M216/25.4 -> 1 | Q216: =N216/25.4 -> 5.5 | R216: =ROUND(IFERROR(1/((M216*N216*0.3048)/1000000),0),3) -> 924.602 | S216: =L216*M216/1000*N216/1000 -> 0.022712471 | T216: =F216&" "&C216 -> Cumaru Grooved 5/4x6 Long
... A646: Cumaru | B646: Cumaru 3x9 | C646: Long | D646: Hardwoods | E646: CM3912S | F646: Cumaru S4S E4E 3x9 | G646: Cumaru | H646: S4S E4E | I646: - | J646: 3x9 | K646: 12 | L646: 3.6576 | M646: 63.5 | N646: 215.9 | O646: =L646/0.0254 -> 144 | P646: =M646/25.4 -> 2.5 | Q646: =N646/25.4 -> 8.5 | R646: =ROUND(IFERROR(1/((M646*N646*0.3048)/1000000),0),3) -> 239.309 | S646: =L646*M646/1000*N646/1000 -> 0.050144416 | T646: =F646&" "&C646 -> Cumaru S4S E4E 3x9 Long
...
